##  异步的实现方式



为了让那些**不是必须**执行完此任务才能继续向下执行的任务妨碍到下面的任务，就可以把此任务变为异步任务，那么如何把一个任务变为异步任务？

1. 回调函数
2. promise
3. generator
4. async 函数



|           |                                                        |
| --------- | ------------------------------------------------------ |
| 回调函数  | 嵌套结构的回调地狱问题                                 |
| Promise   | 将嵌套结构拉成线性结构（链式调用），对成功失败进行处理 |
| generator |                                                        |
| 异步函数  | 基于promise，优化链式调用，使代码更加简洁直观          |

异步操作放到Promsie中，可以对成功或失败进行处理；当需要顺序调用promise时，使用异步函数。



## 回调函数





## promise





### 执行机制



Promise 是一个构造函数，new时接收一个函数作为参数，返回一个 Promise 实例。

一个 Promise 实例有三种状态，分别是pending、fulfilled 和 rejected，分别代表了进行中、已成功和已失败。pending是实例的初始状态，实例的状态只能由 pending 转变 resolved 或者rejected 状态，并且状态一经改变，就凝固了，无法再被改变了。即实例的状态只能改变一次,后面的改变会被忽略。

状态的改变是通过 resolve() 和 reject() 函数来实现的，可以在异步操作结束后根据是否成功来选择调用这两个函数来决定返回的 Promise 实例的状态。

当 Promise实例为成功状态时，回调后跟的 `then()`方法；当 Promise实例为失败状态时，回调后跟的 `catch()`方法；





new Promise()时需要传入一个函数参数，这个函数称为执行器函数

执行到new Promise()时，会立即执行执行器函数中的代码。执行到resolve()/reject()时会调用then()/catch()方法，将其中的回调函数加入事件队列，继续执行下面的代码，等待文件中同步代码执行完成后调用。

```js
let foo;

let p = new Promise((resolve, reject) => {
  foo = function() {
    console.log(1);
    resolve();          
    console.log(2);
  }
})
p.then(() => {console.log(4);});

foo();
console.log(3);

//会按照1234的顺序打印
```

同时也说明，执行到resolve()函数后并不会退出执行器函数。



Promise的缺点：

- 无法取消Promise，一旦新建它就会立即执行，无法中途取消。
- 如果不设置回调函数，Promise内部抛出的错误，不会反应到外部。
- 当处于pending状态时，无法得知目前进展到哪一个阶段（刚刚开始还是即将完成）。





### 基本使用



```js
new Promise((resolve, reject) => {
  
    // ... some code
  
    if (/* 异步操作成功 */){
      resolve(value);               //value和error都是可选的，可以不传
    } else {
      reject(error);
    }
}).then((res) => {                    //then()/catch()/finally()都是可选的
     console.log(res);        
}).catch((err) => {
     console.log(err);           
}).finally(() => {···});        
```

`finally()`表示不论成功失败的Promise实例都会执行的方法，传入的函数参数不接受任何参数。





### 实例方法



then()、catch()、finally()。定义在Promise原型上的方法，Promise实例可以调用。



1. then() 和catch()方法

then()方法可以接收两个函数作为参数，参数中传入非函数参数时会被忽略。

```js
new Promise((resolve, reject) => {
  resolve("成功了");
  // reject("失败了");
}).then(
  (value) => { console.log(value); },          //resolve()时回调
  (err) => {  console.log(err); },             //catch()时回调
);
```

两个函数都是可选的，但当只需要第二个错误处理函数时需要声明为：

```js
p.then(undefined, () => {...});

p.catch(() => {...});                   //catch()方法是此种声明的语法糖
               
p.then(() => {...})          //有了catch()方法，then()方法一般只回调第一个函数
```





2. Promise实例调用then()、catch()、finally()方法都会返回一个新的Promise实例



Promise实例调用then()方法会返回一个新的Promise实例。该Promise实例基于then()方法中回调函数的返回值构建。

- 当有return值时，通过Promise.resolve()传入返回值创建一个成功状态的Promsie实例返回。特别的：当return一个失败状态的Promise实例时，传入后会返回该失败状态的实例本身。（Promise.resolve()原理，见静态方法）

```js
let p1 = new Promise((resolve, reject) => {
  resolve("成功了");
}).then(value => {              //相当于Promise.resolve(10)
  return 10;
});
console.log(p1);         //Promise {<fulfilled>: 10}
```



- 当没有return值时，通过Promise.resolve()传入undefined创建一个成功状态的Promsie实例返回。特别的：**当没有返回值但抛出未处理的错误时会返回一个失败状态的Promise实例。**

```js
let p1 = new Promise(...)
  .then(value => { 
    console.log(value);
  })                               //相当于Promise.resolve(undefined)

console.log(p1);            //Promise {<fulfilled>: undefined}
```



- 当then()方法中没有对应的回调函数时，通过Promise.resolve()传入value的值创建一个Promsie实例返回；如果没有value值则传入undefined

```js
let p1 = new Promise(...)
  .then()                       //相当于Promise.resolve("成功了")

console.log(p1);            //Promise {<fulfilled>: "成功了"}
```



失败状态的Promise实例调用catch()方法也会返回一个新的Promise实例。都是通过Promsie.resolve()创建一个新的成功状态的Promise实例，原理与then()方法相同。

这里为什么不使用Promsie.reject()？因为catch()方法就是来捕获错误、防止错误阻塞代码的，捕获成功就应该创建一个成功状态的Promise实例。否则传入Promsie.reject()还会再抛出一个错误阻塞代码。



3. 区分理解

```js
let p1 = new Promise((resolve, reject) => {
  resolve();
})
  .then(() => { console.log("res"); })
  .catch(() => { console.log("err"); });


let p2 = new Promise((resolve, reject) => {
  reject();
})
  .catch(() => { console.log("err"); })
  .then(() => { console.log("res"); });
```

前者打印res；后者打印err,res。为什么例2中then()方法还会执行？

例1中Promise实例为成功状态，调用then()方法返回一个成功状态的新Promise实例所以这个实例不会再调用它的catch()方法。例2中Promise实例为失败状态，调用catch()方法也返回一个成功状态的新Promise实例，所以这个实例会继续调用它的then()方法。



4. then()方法的链式调用

调用then()方法会返回一个Promise.resolve()传入return值创建的实例，因为Promise.resolve()传入Promise实例时，会返回实例本身，所以如果then()方法return一个Promise实例，then()方法的返回值就是这个实例。

新创建的Promise对象可以获取到上一个Promsie对象的执行结果，它本身又可以调用then()方法。因此可以采用链式写法，即`then`方法后面再调用另一个then方法。

```js
let promise = new Promise((resolve,reject)=>{
    ajax('first').success((res) => {
        resolve(res);
    })
})
promise.then(res=>{
    return new Promise((resovle,reject)=>{
        ajax('second').success((res) => {
            resolve(res)
        })
    })
}).then(res=>{
    return new Promise((resovle,reject)=>{
        ajax('second').success(function(res){
            resolve(res)
        })
    })
}).then(res=>{
    
})
```



5. finally()方法



不论成功失败状态的Promise实例都会执行的方法，传入的函数参数不接受任何参数。



Promise对象调用finally()方法会返回一个新的Promise实例。此Promise实例大多数情况下表现为父Promise对象的传递。即复制一份调用finally()的Promise实例返回但不是返回该对象本身。

```js
let p1 = Promise.resolve('foo');

let p2 = p1.finally()
let p3 = p1.finally(() => {})
let p4 = p1.finally(() => 10 )
let p5 = p1.finally(() => { return Promise.resolve(); })
let p6 = p1.finally(() => { return new Error('bar') })

//打印一下 p2,p3...p6
//全都返回 Promise<resolved>: foo
//返回的都是p1的复制
```

特殊的，当finally()方法中的回调函数return一个待定状态的Promise实例时，finally()方法返回该待定状态的Promise实例。

```js
let p1 = Promise.resolve('foo');

let p2 = p1.finally(() => {
  return new Promise(() => {})
})
// Promise<pending>: undefined
```

当finally()方法中的回调函数return一个失败状态的Promise实例或抛出一个错误时，返回该失败状态的Promise实例。并抛出一个错误。

```js
let p1 = Promise.resolve('foo');

let p2 = p1.finally(() => {
  return Promise.reject(new Error('foo'))
})

let p3 = p1.finally(() => {
  throw new Error('foo')
})

// Promise<rejected>: Error
//Uncaught (in promise) Error: foo
// Promise<rejected>: Error
//Uncaught (in promise) Error: foo
```





### 静态方法



Promise.resolve()、Promise.reject()、Promise.all()、Promise.race()。定义在Promise构造函数上的静态方法，直接由Promise调用：



1. Promise.resolve()和Promise.reject()



Promise对象并非一开始就只能是进行中的状态，可以通过Promise.resolve()和Promise.reject()直接创建一个成功状态和失败状态的Promise对象。



Promise.resolve()相当于直接新建了一个成功状态的 Promise对象

```js
let p1 = Promise.resolve();             //Promise {<fulfilled>: undefined}
let p2 = new Promise((resolve, reject) => resolve());


// 第一个参数会成为value值，多余的参数会被忽略
let p1 = Promise.resolve(10)
  .then((res) => {
    console.log(res);                                 //10
  });


// Promise.resolve()可以将任意一个非Promise实例的值转为一个Promise实例，如果传入的是一个Promise实例，则返回该实例本身。
let p1 = Promise.resolve()
let p = Promise.resolve(p1)
console.log(p === p1);                    //true
```



同理，Promise.reject()相当于直接新建了一个失败状态的 Promise对象，并抛出一个不能被try/catch捕获的错误。

```js
let p1 = Promise.reject();
let p2 = new Promise((resolve, reject) => reject());


// 第一个参数会成为err值，多余的参数会被忽略
let p1 = Promise.reject(10)
  .catch((err) => {
    console.log(err);                                 //10
  });


// 与Promise.resolve()不同的是，传入任何值都会返回一个失败状态的Promise对象，包括Promise对象，会成为err的值
let p1 = Promise.reject()
let p = Promise.resolve(p1)
console.log(p === p1);                    //false
```

另外，会抛出一个异步错误，这个错误不能被 try/catch获取，只能通过 catch()方法获取

```js
try {
  Promise.reject(10);
} catch(e) {
  console.log(e);
}

//没有打印e，即 try/catchm而是报错 Uncaught (in promise) 10
```





2. Promise.all()

可以将多个 Promise实例包装成一个新的 Promise实例。每个 Promise都成功了，回调 `then()`；只要有一个失败了，回调 `catch()`；只要有一个处于待定状态，则处于待定状态。

```js
let p1 = Promise.resolve("p1成功了");
let p2 = Promise.resolve("p2成功了");
let p3 = Promise.reject("3失败了");

Promise.all([p1, p2])              //接收一个Promise实例数组作为参数
.then((res) => {
    console.log(res)               //["p1成功了", "p2成功了"]
}).catch((err) => {
    console.log(err)
})

Promise.all([p1, p3, p2])
.then((result) => {
    console.log(result)
}).catch((error) => {
    console.log(error)      // p3失败了
})
```

注意！成功后的结果按传入的数组参数中 Promise实例的顺序返回，而不是各个实例中异步操作的完成顺序；失败后返回第一个异步操作失败的结果（err），只会返回第一个再有失败的也不会返回了,会被静默处理抛出的错误。

即：成功和失败的返回值是不同的，成功的时候返回的是**一个结果数组**，而失败的时候则返回第一个异步操作失败的结果。 



3. Promise.race()

包装第一个成功或失败的Promise实例的解决值或拒绝理由返回一个新Promise实例

```js
let p1 = Promise.resolve(10);
let p2 = new Promise((res,rej) => setTimeout(res(), 1000))
let p = Promise.race([p1, p2])

console.log(p1);               //Promise<resolved>: 10
console.log(p);                //Promise<resolved>: 10
console.log(p1 === p);         //false

let p1 = Promise.reject(10);
...
console.log(p1);               //Promise<rejected>: 10
console.log(p);                //Promise<rejected>: 10
console.log(p1 === p);         //false
```

当要做一件事，超过多长时间就不做了，可以用这个方法来解决：

```js
Promise.race([promise1,timeOutPromise(5000)]).then(res=>{})
```





### 抛出错误



第一点：

在Promise的执行器函数和then、catch、fanally处理器函数中抛出**未处理的**错误时，会返回一个失败状态的Promise实例。

1. 在执行器函数和then、catch、fanally处理器函数中可以通过try/actch的方法捕获错误。

```js
const p = new Promise((resolve, reject) => {
  try {
    throw new Error('foo')
  } catch (error) {
    console.log(error);
  }
})
```

2. 可以后跟catch方法捕获错误

```js
const p = new Promise((resolve, reject) => {
  throw new Error('foo')
}).catch(err => {
  console.log(err);
})
```



第二点：

同步代码中抛出错误会立即阻塞代码，但如果错误在then()方法的回调函数中抛出不会立刻阻塞代码，因为回调函数会被添加到事件队列中，等到回调函数被执行的时候才会抛出异常并阻塞代码。

```js
Promise.resolve().then(() => { 
  throw Error('foo');
  console.log("world");
})
console.log("hello");

//hello
//Uncaught (in promise) Error: foo           world没有被打印
```



第三点：

try/catch和Promise中的   catch()方法都是为了捕获错误，防止阻塞代码的。这也就是为什么catch()方法返回一个成功状态的Promise实例。

 





## generator（生成器）



generator函数可以在执行过程中随时停止，下次从停止的位置执行。

调用 generator函数返回一个对象，该对象可以调用next()方法。第一次调用 `next()`方法，开始执行函数中的代码，当执行到 `yield`时，退出执行此函数，并返回一个对象。第二次调用 `next()`方法，会从刚才推出的地方继续执行，同样当执行到 `yield`时，退出执行此函数，并返回一个对象。直到执行到`return`



```js
function* foo() {            //定义一个generator函数
    yield 1;
    yield 2;
    return '结束了';
}
const instance = foo();

console.log(instance.next());     //Object { value: 1, done: false }
console.log(instance.next());     //Object { value: 2, done: false }
console.log(instance.next());     //Object { value: "结束了", done: true }
console.log(instance.next());     //Object { value: undefined, done: true }
```

返回的对象有两个属性：value：yield的返回值；done：表示函数是否执行完成，执行到 return时才会为 true。

调用 `next()`方法执行到 return 后再调用 `next()`方法返回的对象中 value的值为 undifined。

一个对象不断调用 `next()`方法也只能执行一遍函数。调用 `foo()`方法返回一个新对象，使用这个新对象调用 `next()`方法就可以又执行一遍函数



generator函数具体应用

```js
```







## 异步函数



### 调用返回期约

调用异步函数会通过 Promise.resolve()传入返回值返回一个成功状态的Promise实例（没有返回值传入undefined)；抛出未处理的错误会返回失败的Promise实例，可以调用catch捕获错误。

```js
async function foo() {            //在函数定义前添加 async关键字成为异步函数
   return 12;
}
const p = foo();              
console.log(p);               //Promise {<fulfilled>: 12}
```





### 基本使用

可以在异步函数中使用 await关键字优化 Promise中 then的链式调用。

```js
function testAsy(x) {
  return new Promise(resolve => {
    console.log('bar') 
    setTimeout(() => {
      resolve(x);                 //3s之后返回传入的参数x
    }, 3000)
  })
}
async function testAwt() {               
  let result = await testAsy('hello world').catch(err=>                                         {console.log(err);});
  console.log(result);    
  console.log('cuger')   
}
testAwt();
console.log('cug')；

//bar
//cug      
3s之后
//hello world
//cuger
```

1. await关键字后接返回 Promise对象的函数：

调用异步函数执行到 await表达式时，执行Promsie中的代码，当同步代码执行完后会跳出异步函数执行异步函数下面的代码。等到调用resolve时await表达式本身返回resolve的值，再将await表达式下面的代码放到微任务队列中。

即await表达式的值为期约resolve的值，异步函数中该await表达式后面的代码都可以当作它的then方法中的代码

2. await关键字后接原始数据

```js
let result = await 'bar'                  //result='bar'
let result = await Promise.resolve('bar') //result='bar'
```

后接原始数据时，相当于被Promise.resolve()包装，所以最后会返回值本身。 



可以拿到Promise实例resolve的值在下面定义操作，就像then一样；并且此次异步的结果还可以作为下一个异步的传入值，达到了 then的链式调用的效果，但代码没有那么多 `then`看起来更加简洁，就像同步代码一样。



### 错误处理

1. 异步函数中抛出未处理的错误，调用异步函数时会返回失败状态的Promise实例，可以调用catch捕获错误

```js
async function foo() {        
  throw new Error('foo')
}
const p = foo()
console.log(p);                 //Promise {<rejected>: Error: foo}
p.catch(err => {
  console.log(err);            //Error: foo
})
```

2. 异步函数中失败状态的promise实例抛出的错误不会被调用异步函数返回的期约捕获到

```js
async function foo() {        
  Promise.reject(3)
}
const p = foo()
console.log(p);                 //Promise {<fulfilled>: undefined}
p.catch(err => {
  console.log(err);            //没有打印，报错Uncaught (in promise) 3
})
```

使用await后可以被捕获到

```js
async function foo() {        
  await Promise.reject(3)
}
const p = foo()
console.log(p);                 //Promise {<rejected>: 3}
p.catch(err => {
  console.log(err);            //3
})
```

3. 在异步函数中除了调用catch方法外还可以使用try/catch捕获错误

```js
async function foo() {
  try {
    let result1 = await testAsy('hello world');
    let result2 = await testAsy('hello');
  } catch (error) {
    console.log(error);          //只会打印第一个错误
  }
}
foo()
```





同样，await表达式也支持 `Promise.all()`、`Promise.race()`

```js
let values = await Promise.all([coffee, tea, description]);
```





面试题

```js
async function async1 () {
  console.log('async1 start')
  await async2();
  console.log('async1 end')
}
 
async function async2 () {
  console.log('async2')
}

console.log('script start')
 
setTimeout(function () {
  console.log('setTimeout')
}, 0)
 
async1();
 
new Promise (function (resolve) {
  console.log('promise1')
  resolve();
}).then (function () {
  console.log('promise2')
})

console.log('script end')
```

结果

```js
script start
async1 start
async2
promise1
script end
async1 end
promise2
setTimeout
```

